Traceback (most recent call last):
  File "/home/ubuntu/varuna_examples/Megatron-LM/pretrain_gpt2.py", line 170, in <module>
    pretrain(train_valid_test_datasets_provider, model_provider, forward_step,
  File "/home/ubuntu/varuna_examples/Megatron-LM/megatron/training.py", line 131, in pretrain
    iteration = train(forward_step_func if not args.varuna else varuna_step_func,
  File "/home/ubuntu/varuna_examples/Megatron-LM/megatron/training.py", line 519, in train
    save_checkpoint(iteration, model, optimizer, lr_scheduler)
  File "/home/ubuntu/varuna_examples/Megatron-LM/megatron/checkpointing.py", line 141, in save_checkpoint
    torch.distributed.barrier()
  File "/opt/conda/envs/varuna/lib/python3.9/site-packages/torch/distributed/distributed_c10d.py", line 2783, in barrier
    work.wait()
RuntimeError: [/opt/conda/conda-bld/pytorch_1646755888534/work/third_party/gloo/gloo/transport/tcp/pair.cc:598] Connection closed by peer [172.31.20.223]:13733
Traceback (most recent call last):
  File "/home/ubuntu/varuna_examples/Megatron-LM/pretrain_gpt2.py", line 170, in <module>
    pretrain(train_valid_test_datasets_provider, model_provider, forward_step,
  File "/home/ubuntu/varuna_examples/Megatron-LM/megatron/training.py", line 103, in pretrain
    model, optimizer, lr_scheduler = setup_model_and_optimizer(model_provider, get_batch_fn)
  File "/home/ubuntu/varuna_examples/Megatron-LM/megatron/training.py", line 268, in setup_model_and_optimizer
    model, profiler = get_model(model_provider_func, get_batch_fn)
  File "/home/ubuntu/varuna_examples/Megatron-LM/megatron/training.py", line 172, in get_model
    model = Varuna( model, args.stage_to_rank_map, get_batch_fn, global_batch_size,
  File "/home/ubuntu/varuna/varuna/varuna.py", line 132, in __init__
    self.model.initialize( get_batch_fn, from_cache=from_cache )
  File "/home/ubuntu/varuna/varuna/partitioned_model.py", line 224, in initialize
    self.dry_run(get_batch_fn, from_cache)
  File "/home/ubuntu/varuna/varuna/partitioned_model.py", line 242, in dry_run
    dist.barrier()
  File "/opt/conda/envs/varuna/lib/python3.9/site-packages/torch/distributed/distributed_c10d.py", line 2783, in barrier
    work.wait()
RuntimeError: [/opt/conda/conda-bld/pytorch_1646755888534/work/third_party/gloo/gloo/transport/tcp/pair.cc:598] Connection closed by peer [172.31.21.45]:57253
Traceback (most recent call last):
  File "/home/ubuntu/varuna_examples/Megatron-LM/pretrain_gpt2.py", line 170, in <module>
    pretrain(train_valid_test_datasets_provider, model_provider, forward_step,
  File "/home/ubuntu/varuna_examples/Megatron-LM/megatron/training.py", line 103, in pretrain
    model, optimizer, lr_scheduler = setup_model_and_optimizer(model_provider, get_batch_fn)
  File "/home/ubuntu/varuna_examples/Megatron-LM/megatron/training.py", line 280, in setup_model_and_optimizer
    args.iteration = load_checkpoint(model, optimizer, lr_scheduler)
  File "/home/ubuntu/varuna_examples/Megatron-LM/megatron/checkpointing.py", line 285, in load_checkpoint
    torch.distributed.barrier()
  File "/opt/conda/envs/varuna/lib/python3.9/site-packages/torch/distributed/distributed_c10d.py", line 2783, in barrier
    work.wait()
RuntimeError: [/opt/conda/conda-bld/pytorch_1646755888534/work/third_party/gloo/gloo/transport/tcp/pair.cc:598] Connection closed by peer [172.31.21.137]:26029
Traceback (most recent call last):
  File "/home/ubuntu/varuna_examples/Megatron-LM/pretrain_gpt2.py", line 170, in <module>
    pretrain(train_valid_test_datasets_provider, model_provider, forward_step,
  File "/home/ubuntu/varuna_examples/Megatron-LM/megatron/training.py", line 103, in pretrain
    model, optimizer, lr_scheduler = setup_model_and_optimizer(model_provider, get_batch_fn)
  File "/home/ubuntu/varuna_examples/Megatron-LM/megatron/training.py", line 280, in setup_model_and_optimizer
    args.iteration = load_checkpoint(model, optimizer, lr_scheduler)
  File "/home/ubuntu/varuna_examples/Megatron-LM/megatron/checkpointing.py", line 285, in load_checkpoint
    torch.distributed.barrier()
  File "/opt/conda/envs/varuna/lib/python3.9/site-packages/torch/distributed/distributed_c10d.py", line 2783, in barrier
    work.wait()
RuntimeError: [/opt/conda/conda-bld/pytorch_1646755888534/work/third_party/gloo/gloo/transport/tcp/pair.cc:598] Connection closed by peer [172.31.28.143]:22962
Traceback (most recent call last):
  File "/home/ubuntu/varuna_examples/Megatron-LM/pretrain_gpt2.py", line 170, in <module>
    pretrain(train_valid_test_datasets_provider, model_provider, forward_step,
  File "/home/ubuntu/varuna_examples/Megatron-LM/megatron/training.py", line 103, in pretrain
    model, optimizer, lr_scheduler = setup_model_and_optimizer(model_provider, get_batch_fn)
  File "/home/ubuntu/varuna_examples/Megatron-LM/megatron/training.py", line 268, in setup_model_and_optimizer
    model, profiler = get_model(model_provider_func, get_batch_fn)
  File "/home/ubuntu/varuna_examples/Megatron-LM/megatron/training.py", line 172, in get_model
    model = Varuna( model, args.stage_to_rank_map, get_batch_fn, global_batch_size,
  File "/home/ubuntu/varuna/varuna/varuna.py", line 132, in __init__
    self.model.initialize( get_batch_fn, from_cache=from_cache )
  File "/home/ubuntu/varuna/varuna/partitioned_model.py", line 224, in initialize
    self.dry_run(get_batch_fn, from_cache)
  File "/home/ubuntu/varuna/varuna/partitioned_model.py", line 242, in dry_run
    dist.barrier()
  File "/opt/conda/envs/varuna/lib/python3.9/site-packages/torch/distributed/distributed_c10d.py", line 2783, in barrier
    work.wait()
RuntimeError: [/opt/conda/conda-bld/pytorch_1646755888534/work/third_party/gloo/gloo/transport/tcp/pair.cc:598] Connection closed by peer [172.31.24.82]:2980
Traceback (most recent call last):
  File "/home/ubuntu/varuna_examples/Megatron-LM/pretrain_gpt2.py", line 170, in <module>
    pretrain(train_valid_test_datasets_provider, model_provider, forward_step,
  File "/home/ubuntu/varuna_examples/Megatron-LM/megatron/training.py", line 90, in pretrain
    initialize_megatron(extra_args_provider=extra_args_provider,
  File "/home/ubuntu/varuna_examples/Megatron-LM/megatron/initialize.py", line 74, in initialize_megatron
    finish_mpu_init()
  File "/home/ubuntu/varuna_examples/Megatron-LM/megatron/initialize.py", line 56, in finish_mpu_init
    _initialize_distributed()
  File "/home/ubuntu/varuna_examples/Megatron-LM/megatron/initialize.py", line 119, in _initialize_distributed
    torch.distributed.init_process_group(
  File "/opt/conda/envs/varuna/lib/python3.9/site-packages/torch/distributed/distributed_c10d.py", line 595, in init_process_group
    store, rank, world_size = next(rendezvous_iterator)
  File "/opt/conda/envs/varuna/lib/python3.9/site-packages/torch/distributed/rendezvous.py", line 186, in _tcp_rendezvous_handler
    store = _create_c10d_store(result.hostname, result.port, rank, world_size, timeout)
  File "/opt/conda/envs/varuna/lib/python3.9/site-packages/torch/distributed/rendezvous.py", line 160, in _create_c10d_store
    return TCPStore(
  File "/home/ubuntu/varuna_examples/Megatron-LM/pretrain_gpt2.py", line 164, in handler
    print('Rank', torch.distributed.get_rank(), 'signal handler called with signal', signum, flush=True)
  File "/opt/conda/envs/varuna/lib/python3.9/site-packages/torch/distributed/distributed_c10d.py", line 844, in get_rank
    default_pg = _get_default_group()
  File "/opt/conda/envs/varuna/lib/python3.9/site-packages/torch/distributed/distributed_c10d.py", line 429, in _get_default_group
    raise RuntimeError(
RuntimeError: Default process group has not been initialized, please make sure to call init_process_group.
Traceback (most recent call last):
  File "/home/ubuntu/varuna_examples/Megatron-LM/pretrain_gpt2.py", line 170, in <module>
    pretrain(train_valid_test_datasets_provider, model_provider, forward_step,
  File "/home/ubuntu/varuna_examples/Megatron-LM/megatron/training.py", line 131, in pretrain
    iteration = train(forward_step_func if not args.varuna else varuna_step_func,
  File "/home/ubuntu/varuna_examples/Megatron-LM/megatron/training.py", line 519, in train
    save_checkpoint(iteration, model, optimizer, lr_scheduler)
  File "/home/ubuntu/varuna_examples/Megatron-LM/megatron/checkpointing.py", line 149, in save_checkpoint
    torch.distributed.barrier()
  File "/opt/conda/envs/varuna/lib/python3.9/site-packages/torch/distributed/distributed_c10d.py", line 2783, in barrier
    work.wait()
RuntimeError: [/opt/conda/conda-bld/pytorch_1646755888534/work/third_party/gloo/gloo/transport/tcp/pair.cc:598] Connection closed by peer [172.31.26.140]:26543
Traceback (most recent call last):
  File "/home/ubuntu/varuna_examples/Megatron-LM/pretrain_gpt2.py", line 170, in <module>
    pretrain(train_valid_test_datasets_provider, model_provider, forward_step,
  File "/home/ubuntu/varuna_examples/Megatron-LM/megatron/training.py", line 131, in pretrain
    iteration = train(forward_step_func if not args.varuna else varuna_step_func,
  File "/home/ubuntu/varuna_examples/Megatron-LM/megatron/training.py", line 519, in train
    save_checkpoint(iteration, model, optimizer, lr_scheduler)
  File "/home/ubuntu/varuna_examples/Megatron-LM/megatron/checkpointing.py", line 141, in save_checkpoint
    torch.distributed.barrier()
  File "/opt/conda/envs/varuna/lib/python3.9/site-packages/torch/distributed/distributed_c10d.py", line 2783, in barrier
    work.wait()
RuntimeError: [/opt/conda/conda-bld/pytorch_1646755888534/work/third_party/gloo/gloo/transport/tcp/pair.cc:598] Connection closed by peer [172.31.22.229]:4487
